Workbook

Sheet Unit_Balance
A1: Unit_ID | B1: Unit_Name | C1: Faction | D1: Role | E1: Attack_Type | F1: HP | G1: Damage | H1: Attack_Interval | I1: DPS | J1: Attack_Range | K1: Move_Speed | L1: Cost | M1: HP_per_Cost | N1: DPS_per_Cost
A2: UND_01 | B2: Skeleton Swordsman | C2: Undead | D2: Infantry | E2: Melee | F2: =VLOOKUP("Baseline_HP",Balance_Config!$A:$B,2,FALSE)*VLOOKUP(D2&"_HP_Modifier",Balance_Config!$A:$B,2,FALSE)*IFERROR(VLOOKUP(A2&"_HP_Modifier",Balance_Config!$A:$B,2,FALSE),1) -> 800 | G2: =VLOOKUP("Baseline_DPS",Balance_Config!$A:$B,2,FALSE)*VLOOKUP(D2&"_DPS_Modifier",Balance_Config!$A:$B,2,FALSE)*IFERROR(VLOOKUP(A2&"_DPS_Modifier",Balance_Config!$A:$B,2,FALSE),1)*H2 -> 81 | H2: =VLOOKUP("Baseline_Attack_Interval",Balance_Config!$A:$B,2,FALSE)*VLOOKUP(D2&"_Attack_Interval_Modifier",Balance_Config!$A:$B,2,FALSE)*IFERROR(VLOOKUP(A2&"_Attack_Interval_Modifier",Balance_Config!$A:$B,2,FALSE),1) -> 0.9 | I2: =G2/H2 -> 90 | J2: =IF(E2="Melee",VLOOKUP("Baseline_Melee_Range",Balance_Config!$A:$B,2,FALSE),VLOOKUP("Baseline_Ranged_Range",Balance_Config!$A:$B,2,FALSE))*IFERROR(VLOOKUP(A2&"_Range_Modifier",Balance_Config!$A:$B,2,FALSE),1) -> 1 | K2: =VLOOKUP("Baseline_Move_Speed",Balance_Config!$A:$B,2,FALSE)*IFERROR(VLOOKUP(A2&"_Move_Speed_Modifier",Balance_Config!$A:$B,2,FALSE),1) -> 2 | L2: 85 | M2: =IF(OR(F2="",L2="",L2=0),"",F2/L2) -> 9.4117647 | N2: =IF(OR(I2="",L2="",L2=0),"",I2/L2) -> 1.0588235
A3: UND_02 | B3: Bone Dragon | C3: Undead | D3: Tank | E3: Melee | F3: =VLOOKUP("Baseline_HP",Balance_Config!$A:$B,2,FALSE)*VLOOKUP(D3&"_HP_Modifier",Balance_Config!$A:$B,2,FALSE)*IFERROR(VLOOKUP(A3&"_HP_Modifier",Balance_Config!$A:$B,2,FALSE),1) -> 1440 | G3: =VLOOKUP("Baseline_DPS",Balance_Config!$A:$B,2,FALSE)*VLOOKUP(D3&"_DPS_Modifier",Balance_Config!$A:$B,2,FALSE)*IFERROR(VLOOKUP(A3&"_DPS_Modifier",Balance_Config!$A:$B,2,FALSE),1)*H3 -> 96 | H3: =VLOOKUP("Baseline_Attack_Interval",Balance_Config!$A:$B,2,FALSE)*VLOOKUP(D3&"_Attack_Interval_Modifier",Balance_Config!$A:$B,2,FALSE)*IFERROR(VLOOKUP(A3&"_Attack_Interval_Modifier",Balance_Config!$A:$B,2,FALSE),1) -> 1.6 | I3: =G3/H3 -> 60 | J3: =IF(E3="Melee",VLOOKUP("Baseline_Melee_Range",Balance_Config!$A:$B,2,FALSE),VLOOKUP("Baseline_Ranged_Range",Balance_Config!$A:$B,2,FALSE))*IFERROR(VLOOKUP(A3&"_Range_Modifier",Balance_Config!$A:$B,2,FALSE),1) -> 1 | K3: =VLOOKUP("Baseline_Move_Speed",Balance_Config!$A:$B,2,FALSE)*IFERROR(VLOOKUP(A3&"_Move_Speed_Modifier",Balance_Config!$A:$B,2,FALSE),1) -> 1.4 | L3: 140 | M3: =IF(OR(F3="",L3="",L3=0),"",F3/L3) -> 10.285714 | N3: =IF(OR(I3="",L3="",L3=0),"",I3/L3) -> 0.42857143
A4: UND_03 | B4: Spear Devil | C4: Undead | D4: Ranged | E4: Ranged | F4: =VLOOKUP("Baseline_HP",Balance_Config!$A:$B,2,FALSE)*VLOOKUP(D4&"_HP_Modifier",Balance_Config!$A:$B,2,FALSE)*IFERROR(VLOOKUP(A4&"_HP_Modifier",Balance_Config!$A:$B,2,FALSE),1) -> 800 | G4: =VLOOKUP("Baseline_DPS",Balance_Config!$A:$B,2,FALSE)*VLOOKUP(D4&"_DPS_Modifier",Balance_Config!$A:$B,2,FALSE)*IFERROR(VLOOKUP(A4&"_DPS_Modifier",Balance_Config!$A:$B,2,FALSE),1)*H4 -> 132 | H4: =VLOOKUP("Baseline_Attack_Interval",Balance_Config!$A:$B,2,FALSE)*VLOOKUP(D4&"_Attack_Interval_Modifier",Balance_Config!$A:$B,2,FALSE)*IFERROR(VLOOKUP(A4&"_Attack_Interval_Modifier",Balance_Config!$A:$B,2,FALSE),1) -> 1.2 | I4: =G4/H4 -> 110 | J4: =IF(E4="Melee",VLOOKUP("Baseline_Melee_Range",Balance_Config!$A:$B,2,FALSE),VLOOKUP("Baseline_Ranged_Range",Balance_Config!$A:$B,2,FALSE))*IFERROR(VLOOKUP(A4&"_Range_Modifier",Balance_Config!$A:$B,2,FALSE),1) -> 5 | K4: =VLOOKUP("Baseline_Move_Speed",Balance_Config!$A:$B,2,FALSE)*IFERROR(VLOOKUP(A4&"_Move_Speed_Modifier",Balance_Config!$A:$B,2,FALSE),1) -> 2.2 | L4: 95 | M4: =IF(OR(F4="",L4="",L4=0),"",F4/L4) -> 8.4210526 | N4: =IF(OR(I4="",L4="",L4=0),"",I4/L4) -> 1.1578947
A5: UND_04 | B5: Witch | C5: Undead | D5: Support | E5: Ranged | F5: =VLOOKUP("Baseline_HP",Balance_Config!$A:$B,2,FALSE)*VLOOKUP(D5&"_HP_Modifier",Balance_Config!$A:$B,2,FALSE)*IFERROR(VLOOKUP(A5&"_HP_Modifier",Balance_Config!$A:$B,2,FALSE),1) -> 700 | G5: =VLOOKUP("Baseline_DPS",Balance_Config!$A:$B,2,FALSE)*VLOOKUP(D5&"_DPS_Modifier",Balance_Config!$A:$B,2,FALSE)*IFERROR(VLOOKUP(A5&"_DPS_Modifier",Balance_Config!$A:$B,2,FALSE),1)*H5 -> 98 | H5: =VLOOKUP("Baseline_Attack_Interval",Balance_Config!$A:$B,2,FALSE)*VLOOKUP(D5&"_Attack_Interval_Modifier",Balance_Config!$A:$B,2,FALSE)*IFERROR(VLOOKUP(A5&"_Attack_Interval_Modifier",Balance_Config!$A:$B,2,FALSE),1) -> 1.4 | I5: =G5/H5 -> 70 | J5: =IF(E5="Melee",VLOOKUP("Baseline_Melee_Range",Balance_Config!$A:$B,2,FALSE),VLOOKUP("Baseline_Ranged_Range",Balance_Config!$A:$B,2,FALSE))*IFERROR(VLOOKUP(A5&"_Range_Modifier",Balance_Config!$A:$B,2,FALSE),1) -> 5 | K5: =VLOOKUP("Baseline_Move_Speed",Balance_Config!$A:$B,2,FALSE)*IFERROR(VLOOKUP(A5&"_Move_Speed_Modifier",Balance_Config!$A:$B,2,FALSE),1) -> 1.6 | L5: 110 | M5: =IF(OR(F5="",L5="",L5=0),"",F5/L5) -> 6.3636364 | N5: =IF(OR(I5="",L5="",L5=0),"",I5/L5) -> 0.63636364
A6: ELF_01 | B6: Elven Swordsman | C6: Forest & Dark Elves | D6: Infantry | E6: Melee | F6: =VLOOKUP("Baseline_HP",Balance_Config!$A:$B,2,FALSE)*VLOOKUP(D6&"_HP_Modifier",Balance_Config!$A:$B,2,FALSE)*IFERROR(VLOOKUP(A6&"_HP_Modifier",Balance_Config!$A:$B,2,FALSE),1) -> 950 | G6: =VLOOKUP("Baseline_DPS",Balance_Config!$A:$B,2,FALSE)*VLOOKUP(D6&"_DPS_Modifier",Balance_Config!$A:$B,2,FALSE)*IFERROR(VLOOKUP(A6&"_DPS_Modifier",Balance_Config!$A:$B,2,FALSE),1)*H6 -> 80 | H6: =VLOOKUP("Baseline_Attack_Interval",Balance_Config!$A:$B,2,FALSE)*VLOOKUP(D6&"_Attack_Interval_Modifier",Balance_Config!$A:$B,2,FALSE)*IFERROR(VLOOKUP(A6&"_Attack_Interval_Modifier",Balance_Config!$A:$B,2,FALSE),1) -> 0.8 | I6: =G6/H6 -> 100 | J6: =IF(E6="Melee",VLOOKUP("Baseline_Melee_Range",Balance_Config!$A:$B,2,FALSE),VLOOKUP("Baseline_Ranged_Range",Balance_Config!$A:$B,2,FALSE))*IFERROR(VLOOKUP(A6&"_Range_Modifier",Balance_Config!$A:$B,2,FALSE),1) -> 1 | K6: =VLOOKUP("Baseline_Move_Speed",Balance_Config!$A:$B,2,FALSE)*IFERROR(VLOOKUP(A6&"_Move_Speed_Modifier",Balance_Config!$A:$B,2,FALSE),1) -> 2.2 | L6: 100 | M6: =IF(OR(F6="",L6="",L6=0),"",F6/L6) -> 9.5 | N6: =IF(OR(I6="",L6="",L6=0),"",I6/L6) -> 1
A7: ELF_02 | B7: Great Forest Bear | C7: Forest & Dark Elves | D7: Tank | E7: Melee | F7: =VLOOKUP("Baseline_HP",Balance_Config!$A:$B,2,FALSE)*VLOOKUP(D7&"_HP_Modifier",Balance_Config!$A:$B,2,FALSE)*IFERROR(VLOOKUP(A7&"_HP_Modifier",Balance_Config!$A:$B,2,FALSE),1) -> 1600 | G7: =VLOOKUP("Baseline_DPS",Balance_Config!$A:$B,2,FALSE)*VLOOKUP(D7&"_DPS_Modifier",Balance_Config!$A:$B,2,FALSE)*IFERROR(VLOOKUP(A7&"_DPS_Modifier",Balance_Config!$A:$B,2,FALSE),1)*H7 -> 96 | H7: =VLOOKUP("Baseline_Attack_Interval",Balance_Config!$A:$B,2,FALSE)*VLOOKUP(D7&"_Attack_Interval_Modifier",Balance_Config!$A:$B,2,FALSE)*IFERROR(VLOOKUP(A7&"_Attack_Interval_Modifier",Balance_Config!$A:$B,2,FALSE),1) -> 1.6 | I7: =G7/H7 -> 60 | J7: =IF(E7="Melee",VLOOKUP("Baseline_Melee_Range",Balance_Config!$A:$B,2,FALSE),VLOOKUP("Baseline_Ranged_Range",Balance_Config!$A:$B,2,FALSE))*IFERROR(VLOOKUP(A7&"_Range_Modifier",Balance_Config!$A:$B,2,FALSE),1) -> 1 | K7: =VLOOKUP("Baseline_Move_Speed",Balance_Config!$A:$B,2,FALSE)*IFERROR(VLOOKUP(A7&"_Move_Speed_Modifier",Balance_Config!$A:$B,2,FALSE),1) -> 1.6 | L7: 130 | M7: =IF(OR(F7="",L7="",L7=0),"",F7/L7) -> 12.307692 | N7: =IF(OR(I7="",L7="",L7=0),"",I7/L7) -> 0.46153846
A8: ELF_03 | B8: Elven Mage | C8: Forest & Dark Elves | D8: Ranged | E8: Ranged | F8: =VLOOKUP("Baseline_HP",Balance_Config!$A:$B,2,FALSE)*VLOOKUP(D8&"_HP_Modifier",Balance_Config!$A:$B,2,FALSE)*IFERROR(VLOOKUP(A8&"_HP_Modifier",Balance_Config!$A:$B,2,FALSE),1) -> 800 | G8: =VLOOKUP("Baseline_DPS",Balance_Config!$A:$B,2,FALSE)*VLOOKUP(D8&"_DPS_Modifier",Balance_Config!$A:$B,2,FALSE)*IFERROR(VLOOKUP(A8&"_DPS_Modifier",Balance_Config!$A:$B,2,FALSE),1)*H8 -> 132 | H8: =VLOOKUP("Baseline_Attack_Interval",Balance_Config!$A:$B,2,FALSE)*VLOOKUP(D8&"_Attack_Interval_Modifier",Balance_Config!$A:$B,2,FALSE)*IFERROR(VLOOKUP(A8&"_Attack_Interval_Modifier",Balance_Config!$A:$B,2,FALSE),1) -> 1.2 | I8: =G8/H8 -> 110 | J8: =IF(E8="Melee",VLOOKUP("Baseline_Melee_Range",Balance_Config!$A:$B,2,FALSE),VLOOKUP("Baseline_Ranged_Range",Balance_Config!$A:$B,2,FALSE))*IFERROR(VLOOKUP(A8&"_Range_Modifier",Balance_Config!$A:$B,2,FALSE),1) -> 5.5 | K8: =VLOOKUP("Baseline_Move_Speed",Balance_Config!$A:$B,2,FALSE)*IFERROR(VLOOKUP(A8&"_Move_Speed_Modifier",Balance_Config!$A:$B,2,FALSE),1) -> 1.6 | L8: 110 | M8: =IF(OR(F8="",L8="",L8=0),"",F8/L8) -> 7.2727273 | N8: =IF(OR(I8="",L8="",L8=0),"",I8/L8) -> 1
A9: ELF_04 | B9: Elven Scholar | C9: Forest & Dark Elves | D9: Support | E9: Ranged | F9: =VLOOKUP("Baseline_HP",Balance_Config!$A:$B,2,FALSE)*VLOOKUP(D9&"_HP_Modifier",Balance_Config!$A:$B,2,FALSE)*IFERROR(VLOOKUP(A9&"_HP_Modifier",Balance_Config!$A:$B,2,FALSE),1) -> 700 | G9: =VLOOKUP("Baseline_DPS",Balance_Config!$A:$B,2,FALSE)*VLOOKUP(D9&"_DPS_Modifier",Balance_Config!$A:$B,2,FALSE)*IFERROR(VLOOKUP(A9&"_DPS_Modifier",Balance_Config!$A:$B,2,FALSE),1)*H9 -> 98 | H9: =VLOOKUP("Baseline_Attack_Interval",Balance_Config!$A:$B,2,FALSE)*VLOOKUP(D9&"_Attack_Interval_Modifier",Balance_Config!$A:$B,2,FALSE)*IFERROR(VLOOKUP(A9&"_Attack_Interval_Modifier",Balance_Config!$A:$B,2,FALSE),1) -> 1.4 | I9: =G9/H9 -> 70 | J9: =IF(E9="Melee",VLOOKUP("Baseline_Melee_Range",Balance_Config!$A:$B,2,FALSE),VLOOKUP("Baseline_Ranged_Range",Balance_Config!$A:$B,2,FALSE))*IFERROR(VLOOKUP(A9&"_Range_Modifier",Balance_Config!$A:$B,2,FALSE),1) -> 5 | K9: =VLOOKUP("Baseline_Move_Speed",Balance_Config!$A:$B,2,FALSE)*IFERROR(VLOOKUP(A9&"_Move_Speed_Modifier",Balance_Config!$A:$B,2,FALSE),1) -> 2 | L9: 120 | M9: =IF(OR(F9="",L9="",L9=0),"",F9/L9) -> 5.8333333 | N9: =IF(OR(I9="",L9="",L9=0),"",I9/L9) -> 0.58333333
A10: HOR_01 | B10: Blade Goblin | C10: Horde | D10: Infantry | E10: Melee | F10: =VLOOKUP("Baseline_HP",Balance_Config!$A:$B,2,FALSE)*VLOOKUP(D10&"_HP_Modifier",Balance_Config!$A:$B,2,FALSE)*IFERROR(VLOOKUP(A10&"_HP_Modifier",Balance_Config!$A:$B,2,FALSE),1) -> 900 | G10: =VLOOKUP("Baseline_DPS",Balance_Config!$A:$B,2,FALSE)*VLOOKUP(D10&"_DPS_Modifier",Balance_Config!$A:$B,2,FALSE)*IFERROR(VLOOKUP(A10&"_DPS_Modifier",Balance_Config!$A:$B,2,FALSE),1)*H10 -> 71.25 | H10: =VLOOKUP("Baseline_Attack_Interval",Balance_Config!$A:$B,2,FALSE)*VLOOKUP(D10&"_Attack_Interval_Modifier",Balance_Config!$A:$B,2,FALSE)*IFERROR(VLOOKUP(A10&"_Attack_Interval_Modifier",Balance_Config!$A:$B,2,FALSE),1) -> 0.95 | I10: =G10/H10 -> 75 | J10: =IF(E10="Melee",VLOOKUP("Baseline_Melee_Range",Balance_Config!$A:$B,2,FALSE),VLOOKUP("Baseline_Ranged_Range",Balance_Config!$A:$B,2,FALSE))*IFERROR(VLOOKUP(A10&"_Range_Modifier",Balance_Config!$A:$B,2,FALSE),1) -> 1 | K10: =VLOOKUP("Baseline_Move_Speed",Balance_Config!$A:$B,2,FALSE)*IFERROR(VLOOKUP(A10&"_Move_Speed_Modifier",Balance_Config!$A:$B,2,FALSE),1) -> 2.4 | L10: 90 | M10: =IF(OR(F10="",L10="",L10=0),"",F10/L10) -> 10 | N10: =IF(OR(I10="",L10="",L10=0),"",I10/L10) -> 0.83333333
A11: HOR_02 | B11: Stone Ogre | C11: Horde | D11: Tank | E11: Melee | F11: =VLOOKUP("Baseline_HP",Balance_Config!$A:$B,2,FALSE)*VLOOKUP(D11&"_HP_Modifier",Balance_Config!$A:$B,2,FALSE)*IFERROR(VLOOKUP(A11&"_HP_Modifier",Balance_Config!$A:$B,2,FALSE),1) -> 1760 | G11: =VLOOKUP("Baseline_DPS",Balance_Config!$A:$B,2,FALSE)*VLOOKUP(D11&"_DPS_Modifier",Balance_Config!$A:$B,2,FALSE)*IFERROR(VLOOKUP(A11&"_DPS_Modifier",Balance_Config!$A:$B,2,FALSE),1)*H11 -> 96 | H11: =VLOOKUP("Baseline_Attack_Interval",Balance_Config!$A:$B,2,FALSE)*VLOOKUP(D11&"_Attack_Interval_Modifier",Balance_Config!$A:$B,2,FALSE)*IFERROR(VLOOKUP(A11&"_Attack_Interval_Modifier",Balance_Config!$A:$B,2,FALSE),1) -> 1.6 | I11: =G11/H11 -> 60 | J11: =IF(E11="Melee",VLOOKUP("Baseline_Melee_Range",Balance_Config!$A:$B,2,FALSE),VLOOKUP("Baseline_Ranged_Range",Balance_Config!$A:$B,2,FALSE))*IFERROR(VLOOKUP(A11&"_Range_Modifier",Balance_Config!$A:$B,2,FALSE),1) -> 1 | K11: =VLOOKUP("Baseline_Move_Speed",Balance_Config!$A:$B,2,FALSE)*IFERROR(VLOOKUP(A11&"_Move_Speed_Modifier",Balance_Config!$A:$B,2,FALSE),1) -> 1 | L11: 150 | M11: =IF(OR(F11="",L11="",L11=0),"",F11/L11) -> 11.733333 | N11: =IF(OR(I11="",L11="",L11=0),"",I11/L11) -> 0.4
A12: HOR_03 | B12: Orc Thrower | C12: Horde | D12: Ranged | E12: Ranged | F12: =VLOOKUP("Baseline_HP",Balance_Config!$A:$B,2,FALSE)*VLOOKUP(D12&"_HP_Modifier",Balance_Config!$A:$B,2,FALSE)*IFERROR(VLOOKUP(A12&"_HP_Modifier",Balance_Config!$A:$B,2,FALSE),1) -> 800 | G12: =VLOOKUP("Baseline_DPS",Balance_Config!$A:$B,2,FALSE)*VLOOKUP(D12&"_DPS_Modifier",Balance_Config!$A:$B,2,FALSE)*IFERROR(VLOOKUP(A12&"_DPS_Modifier",Balance_Config!$A:$B,2,FALSE),1)*H12 -> 132 | H12: =VLOOKUP("Baseline_Attack_Interval",Balance_Config!$A:$B,2,FALSE)*VLOOKUP(D12&"_Attack_Interval_Modifier",Balance_Config!$A:$B,2,FALSE)*IFERROR(VLOOKUP(A12&"_Attack_Interval_Modifier",Balance_Config!$A:$B,2,FALSE),1) -> 1.2 | I12: =G12/H12 -> 110 | J12: =IF(E12="Melee",VLOOKUP("Baseline_Melee_Range",Balance_Config!$A:$B,2,FALSE),VLOOKUP("Baseline_Ranged_Range",Balance_Config!$A:$B,2,FALSE))*IFERROR(VLOOKUP(A12&"_Range_Modifier",Balance_Config!$A:$B,2,FALSE),1) -> 4 | K12: =VLOOKUP("Baseline_Move_Speed",Balance_Config!$A:$B,2,FALSE)*IFERROR(VLOOKUP(A12&"_Move_Speed_Modifier",Balance_Config!$A:$B,2,FALSE),1) -> 1.9 | L12: 100 | M12: =IF(OR(F12="",L12="",L12=0),"",F12/L12) -> 8 | N12: =IF(OR(I12="",L12="",L12=0),"",I12/L12) -> 1.1
A13: HOR_04 | B13: Boneclub Troll | C13: Horde | D13: Support | E13: Melee | F13: =VLOOKUP("Baseline_HP",Balance_Config!$A:$B,2,FALSE)*VLOOKUP(D13&"_HP_Modifier",Balance_Config!$A:$B,2,FALSE)*IFERROR(VLOOKUP(A13&"_HP_Modifier",Balance_Config!$A:$B,2,FALSE),1) -> 700 | G13: =VLOOKUP("Baseline_DPS",Balance_Config!$A:$B,2,FALSE)*VLOOKUP(D13&"_DPS_Modifier",Balance_Config!$A:$B,2,FALSE)*IFERROR(VLOOKUP(A13&"_DPS_Modifier",Balance_Config!$A:$B,2,FALSE),1)*H13 -> 98 | H13: =VLOOKUP("Baseline_Attack_Interval",Balance_Config!$A:$B,2,FALSE)*VLOOKUP(D13&"_Attack_Interval_Modifier",Balance_Config!$A:$B,2,FALSE)*IFERROR(VLOOKUP(A13&"_Attack_Interval_Modifier",Balance_Config!$A:$B,2,FALSE),1) -> 1.4 | I13: =G13/H13 -> 70 | J13: =IF(E13="Melee",VLOOKUP("Baseline_Melee_Range",Balance_Config!$A:$B,2,FALSE),VLOOKUP("Baseline_Ranged_Range",Balance_Config!$A:$B,2,FALSE))*IFERROR(VLOOKUP(A13&"_Range_Modifier",Balance_Config!$A:$B,2,FALSE),1) -> 1 | K13: =VLOOKUP("Baseline_Move_Speed",Balance_Config!$A:$B,2,FALSE)*IFERROR(VLOOKUP(A13&"_Move_Speed_Modifier",Balance_Config!$A:$B,2,FALSE),1) -> 2.6 | L13: 100 | M13: =IF(OR(F13="",L13="",L13=0),"",F13/L13) -> 7 | N13: =IF(OR(I13="",L13="",L13=0),"",I13/L13) -> 0.7
I14: =IF(OR(G14="",H14="",H14=0),"",G14/H14) | M14: =IF(OR(F14="",L14="",L14=0),"",F14/L14) | N14: =IF(OR(I14="",L14="",L14=0),"",I14/L14)

Sheet Balance_Config
A1: Parameter | B1: Value | C1: Unit
A2: Baseline_HP | B2: 1000 | C2: HP
A3: Baseline_DPS | B3: 100 | C3: damage/sec
A4: Baseline_Cost | B4: 100 | C4: resource
A5: Baseline_Move_Speed | B5: 2 | C5: tiles/sec
A6: Baseline_Melee_Range | B6: 1 | C6: tiles
A7: Baseline_Ranged_Range | B7: 5 | C7: tiles
A8: Baseline_Attack_Interval | B8: 1 | C8: sec
A9: Infantry_HP_Modifier | B9: 1 | C9: multiplier
A10: Tank_HP_Modifier | B10: 1.6 | C10: multiplier
A11: Ranged_HP_Modifier | B11: 0.8 | C11: multiplier
A12: Support_HP_Modifier | B12: 0.7 | C12: multiplier
A14: ="UND_01"&"_HP_Modifier" -> UND_01_HP_Modifier | B14: 0.8 | C14: multiplier
A15: ="ELF_01"&"_HP_Modifier" -> ELF_01_HP_Modifier | B15: 0.95 | C15: multiplier
A16: ="HOR_01"&"_HP_Modifier" -> HOR_01_HP_Modifier | B16: 0.9 | C16: multiplier
A18: ="UND_02"&"_HP_Modifier" -> UND_02_HP_Modifier | B18: 0.9 | C18: multiplier
A19: ="ELF_02"&"_HP_Modifier" -> ELF_02_HP_Modifier | B19: 1 | C19: multiplier
A20: ="HOR_02"&"_HP_Modifier" -> HOR_02_HP_Modifier | B20: 1.1 | C20: multiplier
A22: Infantry_Attack_Interval_Modifier | B22: 1 | C22: multiplier
A23: Tank_Attack_Interval_Modifier | B23: 1.6 | C23: multiplier
A24: Ranged_Attack_Interval_Modifier | B24: 1.2 | C24: multiplier
A25: Support_Attack_Interval_Modifier | B25: 1.4 | C25: multiplier
A27: UND_01_Attack_Interval_Modifier | B27: 0.9 | C27: multiplier
A28: ELF_01_Attack_Interval_Modifier | B28: 0.8 | C28: multiplier
A29: HOR_01_Attack_Interval_Modifier | B29: 0.95 | C29: multiplier
A31: Infantry_DPS_Modifier | B31: 1 | C31: multiplier
A32: Tank_DPS_Modifier | B32: 0.6 | C32: multiplier
A33: Ranged_DPS_Modifier | B33: 1.1 | C33: multiplier
A34: Support_DPS_Modifier | B34: 0.7 | C34: multiplier
A36: UND_01_DPS_Modifier | B36: 0.9 | C36: multiplier
... A57: HOR_04_Move_Speed_Modifier | B57: 1.3 | C57: multiplier

Sheet Faction_Identity
A1: Faction | B1: Core_Playstyle | C1: Strength_1 | D1: Strength_2 | E1: Strength_3 | F1: Weakness_1 | G1: Weakness_2 | H1: Skill_Focus
A2: Undead | B2: Attrition | C2: Recovery | D2: Debuffs | E2: Sustained Pressure | F2: Low Mobility | G2: Low Burst Damage | H2: Resource & Army Management
A3: Forest & Dark Elves | B3: Precision | C3: High Mobility | D3: Long Range | E3: High Unit Value | F3: Low Durability | G3: High Punishment for Mistakes | H3: Positioning & Micro
A4: Horde | B4: Brute Force / Pressure | C4: High HP | D4: Strong Melee | E4: Crowd Control | F4: Low Mobility | G4: Limited Range | H4: Engagement Timing

Sheet Unit_Identity
A1: Unit_ID | B1: Unit_Name | C1: Combat_Function | D1: Strength | E1: Weakness | F1: Signature_Mechanic
A2: UND_01 | B2: =VLOOKUP(A2, Unit_Balance!$A$1:$E$13, 2, FALSE) -> Skeleton Swordsman | C2: Disposable Frontline Infantry | D2: Low Replacement Cost | E2: Low Individual Durability | F2: Reassemble
A3: UND_02 | B3: =VLOOKUP(A3, Unit_Balance!$A$1:$E$13, 2, FALSE) -> Bone Dragon | C3: Sustained Frontline Tank | D3: High Sustain | E3: Low Mobility | F3: Death Feast
A4: UND_03 | B4: =VLOOKUP(A4, Unit_Balance!$A$1:$E$13, 2, FALSE) -> Spear Devil | C4: Sustained Ranged Damage | D4: Consistent Damage | E4: Low Burst Damage | F4: Cursed Spear
A5: UND_04 | B5: =VLOOKUP(A5, Unit_Balance!$A$1:$E$13, 2, FALSE) -> Witch | C5: Enemy Debuff Support | D5: Strong Debuffs | E5: Very Low Durability | F5: Curse
A6: ELF_01 | B6: =VLOOKUP(A6, Unit_Balance!$A$1:$E$13, 2, FALSE) -> Elven Swordsman | C6: Mobile Melee Infantry | D6: High Mobility | E6: Low Durability | F6: Evasive Step
A7: ELF_02 | B7: =VLOOKUP(A7, Unit_Balance!$A$1:$E$13, 2, FALSE) -> Great Forest Bear | C7: Protective Frontline Tank | D7: High Durability | E7: Limited Damage | F7: Guardian Roar
A8: ELF_03 | B8: =VLOOKUP(A8, Unit_Balance!$A$1:$E$13, 2, FALSE) -> Elven Mage | C8: High-Value Ranged Damage | D8: High Damage & Range | E8: Very Low Durability | F8: Focused Bolt
A9: ELF_04 | B9: =VLOOKUP(A9, Unit_Balance!$A$1:$E$13, 2, FALSE) -> Elven Scholar | C9: Protective Magic Support | D9: Strong Ally Protection | E9: Low Direct Damage | F9: Arcane Shield
A10: HOR_01 | B10: =VLOOKUP(A10, Unit_Balance!$A$1:$E$13, 2, FALSE) -> Blade Goblin | C10: Aggressive Melee Infantry | D10: High Melee Damage | E10: Low Durability | F10: Blood Rush
A11: HOR_02 | B11: =VLOOKUP(A11, Unit_Balance!$A$1:$E$13, 2, FALSE) -> Stone Ogre | C11: Heavy Frontline Tank | D11: Very High Durability | E11: Very Low Mobility | F11: Stone Skin
A12: HOR_03 | B12: =VLOOKUP(A12, Unit_Balance!$A$1:$E$13, 2, FALSE) -> Orc Thrower | C12: Short-Range Ranged Pressure | D12: High Attack Rate | E12: Short Range | F12: Knife Barrage
A13: HOR_04 | B13: =VLOOKUP(A13, Unit_Balance!$A$1:$E$13, 2, FALSE) -> Boneclub Troll | C13: Crowd Control Support | D13: Strong Crowd Control | E13: Low Damage | F13: Bone Smash

Sheet Ability_Balance
A1: Ability_ID | B1: Unit_ID | C1: Ability_Name | D1: Ability_Type | E1: Parameter | F1: Value | G1: Unit | H1: Trigger | I1: Target
A2: UND_01_A01 | B2: UND_01 | C2: Reassemble | D2: Triggered | E2: Restore_HP | F2: 35 | G2: % | H2: On Death | I2: Self
A3: UND_01_A01 | B3: UND_01 | C3: Reassemble | D3: Triggered | E3: Delay | F3: 4 | G3: sec | H3: On Death | I3: Self
A4: UND_01_A01 | B4: UND_01 | C4: Reassemble | D4: Triggered | E4: Max_Uses | F4: 1 | G4: count | H4: On Death | I4: Self
A5: UND_02_A01 | B5: UND_02 | C5: Death Feast | D5: Triggered | E5: Heal_Per_Death | F5: 3 | G5: % HP | H5: Nearby Death | I5: Self
A6: UND_02_A01 | B6: UND_02 | C6: Death Feast | D6: Triggered | E6: Trigger_Radius | F6: 5 | G6: tiles | H6: Nearby Death | I6: Self
A7: UND_02_A01 | B7: UND_02 | C7: Death Feast | D7: Triggered | E7: Max_Heal_Per_Second | F7: 6 | G7: % HP/s | H7: Nearby Death | I7: Self
A8: UND_03_A01 | B8: UND_03 | C8: Cursed Spear | D8: Triggered | E8: Damage_Reduction | F8: 15 | G8: % | H8: Every 3 Hits | I8: Single Enemy
A9: UND_03_A01 | B9: UND_03 | C9: Cursed Spear | D9: Triggered | E9: Hits_Required | F9: 3 | G9: hits | H9: Every 3 Hits | I9: Single Enemy
A10: UND_03_A01 | B10: UND_03 | C10: Cursed Spear | D10: Triggered | E10: Duration | F10: 5 | G10: sec | H10: Every 3 Hits | I10: Single Enemy
A11: UND_03_A01 | B11: UND_03 | C11: Cursed Spear | D11: Triggered | E11: Max_Stacks | F11: 1 | G11: count | H11: Every 3 Hits | I11: Single Enemy
A12: UND_03_A01 | B12: UND_03 | C12: Cursed Spear | D12: Triggered | E12: Refresh | F12: 1 | G12: boolean | H12: Reapply | I12: Single Enemy
A13: UND_04_A01 | B13: UND_04 | C13: Curse | D13: Active | E13: Attack_Speed_Reduction | F13: 20 | G13: % | H13: Manual Activation | I13: Single Enemy
... A18: ELF_01_A01 | B18: ELF_01 | C18: Evasive Step | D18: Active | E18: Dash_Distance | F18: 3 | G18: tiles | H18: Manual Activation | I18: Self
A19: ELF_01_A01 | B19: ELF_01 | C19: Evasive Step | D19: Active | E19: Dash_Duration | F19: 0.5 | G19: sec | H19: Manual Activation | I19: Self
A20: ELF_01_A01 | B20: ELF_01 | C20: Evasive Step | D20: Active | E20: Cooldown | F20: 10 | G20: sec | H20: Manual Activation | I20: Self
A21: ELF_01_A01 | B21: ELF_01 | C21: Evasive Step | D21: Active | E21: Invulnerability | F21: 0 | G21: boolean | H21: During Dash | I21: Self
A22: ELF_02_A01 | B22: ELF_02 | C22: Guardian Roar | D22: Active | E22: Taunt_Duration | F22: 46144 | G22: sec | H22: Manual Activation | I22: Nearby Enemies
A23: ELF_02_A01 | B23: ELF_02 | C23: Guardian Roar | D23: Active | E23: Effect_Radius | F23: 3 | G23: tiles | H23: Manual Activation | I23: Nearby Enemies
A24: ELF_02_A01 | B24: ELF_02 | C24: Guardian Roar | D24: Active | E24: Cooldown | F24: 16 | G24: sec | H24: Manual Activation | I24: Nearby Enemies
A25: ELF_03_A01 | B25: ELF_03 | C25: Focused Bolt | D25: Active | E25: Charge_Time | F25: 2 | G25: sec | H25: Manual Activation | I25: Single Enemy
A26: ELF_03_A01 | B26: ELF_03 | C26: Focused Bolt | D26: Active | E26: Damage_Multiplier | F26: 46144 | G26: multiplier | H26: On Cast Complete | I26: Single Enemy
A27: ELF_03_A01 | B27: ELF_03 | C27: Focused Bolt | D27: Active | E27: Cooldown | F27: 12 | G27: sec | H27: On Cast Complete | I27: Self
A28: ELF_03_A01 | B28: ELF_03 | C28: Focused Bolt | D28: Active | E28: Cancel_Cooldown | F28: 2 | G28: sec | H28: On Cast Cancel | I28: Self
A29: ELF_03_A01 | B29: ELF_03 | C29: Focused Bolt | D29: Active | E29: Movement_Allowed | F29: 0 | G29: boolean | H29: During Charge | I29: Self
A30: ELF_04_A01 | B30: ELF_04 | C30: Arcane Shield | D30: Active | E30: Shield_Amount | F30: 350 | G30: HP | H30: Manual Activation | I30: Single Ally
A31: ELF_04_A01 | B31: ELF_04 | C31: Arcane Shield | D31: Active | E31: Duration | F31: 6 | G31: sec | H31: Manual Activation | I31: Single Ally
... A43: HOR_03_A01 | B43: HOR_03 | C43: Knife Barrage | D43: Active | E43: Knife_Count | F43: 5 | G43: count | H43: Manual Activation | I43: Single Enemy
A44: HOR_03_A01 | B44: HOR_03 | C44: Knife Barrage | D44: Active | E44: Damage_Per_Knife | F44: 0.45 | G44: multiplier | H44: On Knife Hit | I44: Single Enemy
A45: HOR_03_A01 | B45: HOR_03 | C45: Knife Barrage | D45: Active | E45: Knife_Interval | F45: 0.2 | G45: sec | H45: During Barrage | I45: Single Enemy
A46: HOR_03_A01 | B46: HOR_03 | C46: Knife Barrage | D46: Active | E46: Cooldown | F46: 10 | G46: sec | H46: On Activation | I46: Self
A47: HOR_03_A01 | B47: HOR_03 | C47: Knife Barrage | D47: Active | E47: Movement_Allowed | F47: 0 | G47: boolean | H47: During Barrage | I47: Self
A48: HOR_04_A01 | B48: HOR_04 | C48: Bone Smash | D48: Active | E48: Damage_Multiplier | F48: 0.5 | G48: multiplier | H48: Manual Activation | I48: Single Enemy
A49: HOR_04_A01 | B49: HOR_04 | C49: Bone Smash | D49: Active | E49: Knockback_Distance | F49: 2 | G49: tiles | H49: On Hit | I49: Single Enemy
A50: HOR_04_A01 | B50: HOR_04 | C50: Bone Smash | D50: Active | E50: Stun_Duration | F50: 46143 | G50: sec | H50: After Knockback | I50: Single Enemy
A51: HOR_04_A01 | B51: HOR_04 | C51: Bone Smash | D51: Active | E51: Cooldown | F51: 14 | G51: sec | H51: On Activation | I51: Self
A52: ELF_01_A01 | B52: ELF_01 | C52: Evasive Step | D52: Active | E52: Pass_Through_Enemies | F52: 0 | G52: boolean | H52: During Dash | I52: Self
A53: ELF_01_A01 | B53: ELF_01 | C53: Evasive Step | D53: Active | E53: Blocked_Path_Cooldown | F53: 10 | G53: sec | H53: On Blocked Dash | I53: Self
A54: ELF_02_A01 | B54: ELF_02 | C54: Guardian Roar | D54: Active | E54: Interrupts_Active_Abilities | F54: 0 | G54: boolean | H54: On Taunt | I54: Nearby Enemies
A55: ELF_02_A01 | B55: ELF_02 | C55: Guardian Roar | D55: Active | E55: Redirects_Future_Multihits | F55: 1 | G55: boolean | H55: During Taunt | I55: Nearby Enemies
...

Sheet Balance_Risks
A1: Risk_ID | B1: Category | C1: Related_Units | D1: Risk_Description | E1: Test_Hypothesis | F1: Status | G1: Evidence_Source | H1: Calculated_Result | I1: Interpretation | J1: Next_Action
A2: RISK_001 | B2: Debuff Synergy | C2: UND_03; UND_04 | D2: Combined Damage and Attack Speed reduction may suppress enemy DPS too strongly | E2: Test combined DPS reduction and target survivability | F2: Analyzed — Needs Playtest | G2: SCN_005 | H2: Combined modifier = (1-15%)*(1-20%) = 0.68; normalized DPS reduction = 32% | I2: Combined Cursed Spear and Curse can substantially reduce sustained enemy DPS when both debuffs are active | J2: Playtest combined debuffs against multiple attacker archetypes and compare TTK
A3: RISK_002 | B3: CC Chain | C3: HOR_04 | D3: Multiple Boneclub Trolls may create excessive consecutive stun duration | E3: Test 1–3 Trolls against a single target | F3: Not Tested | G3: Not calculated yet | H3: Requires tests with 1, 2 and 3 Boneclub Trolls | I3: Current single-target calculations do not determine whether multiple Trolls can create excessive consecutive CC | J3: Create multi-Troll CC-chain scenario
A4: RISK_003 | B4: Defensive Synergy | C4: ELF_02; ELF_04 | D4: Guardian Roar combined with Arcane Shield may make the Bear too difficult to eliminate | E4: Test Bear survivability with and without Arcane Shield | F4: Analyzed — Needs Playtest | G4: SCN_012; SCN_013 | H4: Arcane Shield adds 350 HP to Bear; theoretical effective HP increases from 1600 to 1950 (+21.875%); normalized TTK increases from 16 to 19.5 sec | I4: Arcane Shield can meaningfully increase Bear survivability, but the full theoretical benefit requires the 350 HP shield to be consumed during its 6-sec duration | J4: Playtest Guardian Roar + Arcane Shield against burst and sustained damage; measure shield utilization and actual survivability increase
A5: RISK_004 | B5: Sustain Synergy | C5: UND_01; UND_02 | D5: Reassembled Skeleton may trigger Death Feast again after its second death | E5: Compare Bone Dragon healing with and without Reassemble deaths | F5: Analyzed — Needs Playtest | G5: SCN_006; SCN_007; SCN_008 | H5: Reassemble restores 280 HP; one Death Feast trigger heals 43.2 HP; Death Feast cap = 86.4 HP/sec | I5: Reassembled Skeleton deaths can increase Bone Dragon sustain, but total impact depends on death frequency and positioning | J5: Simulate repeated nearby deaths and compare total Bone Dragon healing
A6: RISK_005 | B6: Debuff Reliability | C6: UND_03 | D6: Cursed Spear may require too much or too little time to activate depending on Spear Devil attack rate | E6: Measure time to reach 3 hits and compare it with typical combat and burst windows | F6: Analyzed — Needs Playtest | G6: SCN_011 | H6: Attack Interval = 1.2 sec; 3 hits require 2 intervals after the first hit; Time_to_Proc = (3-1)*1.2 = 2.4 sec | I6: Cursed Spear requires 2.4 sec from the first successful hit to the third hit that activates the debuff | J6: Validate 2.4-sec Time_to_Proc against burst windows and realistic target movement
A7: RISK_006 | B7: Modifier Interaction | C7: UND_04; HOR_01 | D7: Curse and Blood Rush modify Attack Speed in opposite directions and require a consistent stacking rule | E7: Compare additive and multiplicative modifier models and measure their effect on Goblin DPS | F7: Analyzed — Needs Playtest | G7: SCN_009 | H7: Current multiplicative model: 1.5*0.8 = 1.2; Goblin DPS = 75*1.2 = 90 | I7: Under the current multiplicative model Curse partially offsets Blood Rush without completely cancelling it | J7: Compare multiplicative model with alternative stacking rule and choose one global modifier rule
A8: RISK_007 | B8: Mobility Rule | C8: ELF_01 | D8: Evasive Step behavior is undefined when the dash path is blocked by enemy units | E8: Compare blocked-dash rules and determine which creates clear counterplay without making the ability excessively punishing | F8: Not Tested
A9: RISK_008 | B9: Ability Timing | C9: ELF_02 | D9: Guardian Roar may provide very low value if baited before the main enemy engagement | E9: Test whether the 16-second cooldown creates sufficient punishment for premature activation without making the ability too unreliable | F9: Not Tested
A10: RISK_009 | B10: Projectile Rule | C10: ELF_03 | D10: Focused Bolt target and projectile collision behavior must be defined | E10: Compare target-locked and collision-based targeting to determine which provides clearer counterplay and target-selection depth | F10: Not Tested
A11: RISK_010 | B11: Defensive Cooldown | C11: ELF_04 | D11: Arcane Shield may lose most of its value if enemies can easily switch away from the shielded target | E11: Test whether target switching provides sufficient counterplay without making Arcane Shield too easy to ignore | F11: Not Tested
A12: RISK_011 | B12: Engagement Reliability | C12: HOR_01 | D12: Blade Goblin may be unable to reliably reach melee range and trigger Blood Rush because of its low durability and lack of mobility tools | E12: Measure how often Goblin reaches intended backline targets and how much of the 4-second Blood Rush window is spent dealing effective damage | F12: Not Tested
A13: RISK_012 | B13: Defensive Reliability | C13: HOR_02 | D13: Stone Skin may provide very low value if enemies can disengage or bypass the immobile Stone Ogre during its 4-second duration | E13: Measure prevented damage and enemy target switching during Stone Skin to determine whether immobility creates sufficient counterplay without making the ability too easy to ignore | F13: Not Tested
A14: RISK_013 | B14: Barrage Reliability | C14: HOR_03 | D14: Knife Barrage may lose too much of its potential damage when the target dies or leaves attack range before all five knives are released | E14: Measure average knives landed per Barrage and compare damage efficiency across mobile, fragile, and durable targets | F14: Not Tested
A15: RISK_014 | B15: Knockback Interaction | C15: HOR_04; HOR_03; HOR_01 | D15: Bone Smash knockback may unintentionally move enemies away from allied damage dealers and reduce Horde follow-up damage | E15: Test Bone Smash from different attack angles and measure whether knockback improves or reduces follow-up damage from Goblin and Orc Thrower | F15: Not Tested
A16: RISK_015 | B16: Cost Efficiency | C16: UND_01 | D16: Skeleton Swordsman may provide excessive total combat value for its low cost due to Reassemble | E16: Compare Skeleton cost efficiency and effective survivability before and after the cost increase | F16: Adjusted — Retest Required
A17: RISK_016 | B17: Power Window | C17: HOR_01 | D17: Blood Rush may not create a strong enough temporary offensive threat | E17: Compare Goblin damage output during Blood Rush before and after the Attack Speed bonus increase | F17: Adjusted — Retest Required

Sheet Balance_Summary
A1: Era of Strife — Balance Summary
A2: Project | B2: Mobile RTS META Balance Project | G2: Risk Status | H2: Count
A3: Project_Version | B3: v0.1 | G3: Analyzed — Needs Playtest | H3: =COUNTIF(Balance_Risks!F:F,"Analyzed — Needs Playtest") -> 5
A4: Total_Units | B4: =COUNTA(Unit_Balance!A2:A1000) -> 12 | G4: Not Tested | H4: =COUNTIF(Balance_Risks!F:F,"Not Tested") -> 9
A5: Total_Factions | B5: =IFERROR(__xludf.DUMMYFUNCTION("COUNTUNIQUE(FILTER(Faction_Identity!A2:A1000,Faction_Identity!A2:A1000<>""""))"),3) -> 3 | G5: Blocked by Missing Parameter | H5: =COUNTIF(Balance_Risks!F:F,"Blocked by Missing Parameter") -> 0
A6: Total_Abilities | B6: =IFERROR(__xludf.DUMMYFUNCTION("COUNTUNIQUE(FILTER(Ability_Balance!A2:A1000,Ability_Balance!A2:A1000<>""""))"),12) -> 12 | G6: Adjusted — Retest Required | H6: =COUNTIF(Balance_Risks!F:F,"Adjusted — Retest Required") -> 2
A7: Total_Risks | B7: =COUNTA(Balance_Risks!A2:A1000) -> 16
A8: Analyzed_Risks | B8: =COUNTIF(Balance_Risks!F2:F1000,"Analyzed — Needs Playtest") -> 5
A9: Not_Tested_Risks | B9: =COUNTIF(Balance_Risks!F2:F1000,"Not Tested") -> 9 | G9: Testing Metric | H9: Value
A10: Blocked_Risks | B10: =COUNTIF(Balance_Risks!F2:F1000,"Blocked by Missing Parameter") -> 0 | G10: Analyzed Risks | H10: =B8 -> 5
A11: Retest_Required_Risks | B11: =COUNTIF(Balance_Risks!F2:F1000,"Adjusted — Retest Required") -> 2 | G11: Not Tested Risks | H11: =B9 -> 9
A12: Total_Combat_Scenarios | B12: =COUNTA(Combat_Scenarios!A2:A1000) -> 13 | G12: Blocked Risks | H12: =B10 -> 0
A13: Total_Interactions | B13: =COUNTA(Interaction_Matrix!A2:A1000) -> 29 | G13: Retest Required | H13: =B11 -> 2
A14: Total_Balance_Tests | B14: =COUNTA(Balance_Tests!A2:A1000) -> 8 | G14: Combat Scenarios | H14: =B12 -> 13
G15: Balance Tests | H15: =B14 -> 8
A16: Balance Health Metrics | B16: Value
A17: Analysis_Coverage | B17: =B8/B7 -> 0.3125
A18: Testing_Backlog_Rate | B18: =B9/B7 -> 0.5625 | G18: Balance Effect | H18: Value
A19: Blocked_Risk_Rate | B19: =B10/B7 -> 0 | G19: Undead Combined DPS Reduction | H19: =32% -> 0.32
A20: Retest_Rate | B20: =B11/B7 -> 0.125 | G20: Reassemble Effective HP Increase | H20: =35% -> 0.35
A21: Resolved_or_Analyzed_Rate | B21: =(B8+B11)/B7 -> 0.4375 | G21: Stone Skin Damage Reduction | H21: =40% -> 0.4
A22: Scenarios_Per_Unit | B22: =B12/B4 -> 1.0833333 | G22: Bone Smash / Focused Bolt Charge | H22: =75% -> 0.75
A23: Interactions_Per_Unit | B23: =B13/B4 -> 2.4166667 | G23: Blood Rush DPS Increase under Curse | H23: =20% -> 0.2
A24: Tests_Per_Risk | B24: =B14/B7 -> 0.5
A26: Risk_Status_Check | B26: =IF(B8+B9+B10+B11=B7,"OK","CHECK STATUSES") -> OK
A27: Roster_Structure_Check | B27: =IF(B4=B5*4,"OK","CHECK ROSTER") -> OK
A30: Key Findings | B30: Source | C30: Calculated Evidence | D30: Balance Meaning | E30: Priority / Next Step
A31: Undead Debuff Synergy | B31: RISK_001 / SCN_005 | C31: Combined modifier = (1-15%)*(1-20%) = 0.68; sustained DPS reduced by 32% | D31: Cursed Spear + Curse can substantially suppress sustained enemy damage | E31: High — Playtest against multiple attacker archetypes
A32: Reassemble Sustain | B32: RISK_004 / SCN_006 | C32: Effective Skeleton HP = 800*(1+35%) = 1080; +280 theoretical HP | D32: Reassemble significantly increases Skeleton frontline persistence | E32: High — Validate Reassemble success rate in realistic combat
A33: Death Feast Sustain | B33: RISK_004 / SCN_007; SCN_008 | C33: Heal per death = 1440*3% = 43.2 HP; heal cap = 1440*6% = 86.4 HP/sec | D33: Bone Dragon sustain strongly depends on nearby death frequency | E33: High — Simulate repeated nearby deaths
A34: Blood Rush vs Curse | B34: RISK_006 / SCN_009 | C34: Multiplicative modifier = 1.5*0.8 = 1.2; effective DPS = 75*1.2 = 90 | D34: Curse partially offsets Blood Rush but does not completely cancel it | E34: High — Compare modifier stacking models
A35: Focused Bolt vs Stone Skin | B35: SCN_003 | C35: Focused Bolt = 132*2.5 = 330 damage; after 40% reduction = 330*(1-40%) = 198 damage | D35: Stone Skin creates a meaningful defensive timing window | E35: Medium — Validate timing interaction in combat testing
A36: Knife Barrage Burst | B36: SCN_004 | C36: Maximum barrage damage = 132*2.25 = 297 damage | D36: Full Barrage provides meaningful burst but requires all knives to connect | E36: Medium — Measure hit reliability against moving targets
A37: Bone Smash Interrupt | B37: SCN_010 | C37: Stun / charge ratio = 1.5/2 = 0.75 = 75% | D37: Bone Smash can disrupt a large part of the Focused Bolt charge window | E37: Medium — Test practical interrupt timing
A40: Current Limitations | B40: Reason | C40: Required Data / Action
A41: Cursed Spear Time-to-Proc requires playtest validation | B41: Calculated Time-to-Proc = 2.4 sec; practical reliability is not validated | C41: Validate 2.4-sec Time-to-Proc against burst windows and realistic target movement
A42: Arcane Shield survivability requires playtest validation | B42: Shield_Amount = 350 HP; theoretical survivability impact has been calculated | C42: Playtest Guardian Roar + Arcane Shield against burst and sustained damage
A43: Multi-Troll CC chain is not quantified | B43: Current scenario covers one Bone Smash | C43: Create scenarios with 1, 2 and 3 Boneclub Trolls
A44: Combat scenarios are deterministic | B44: Current calculations do not include movement, targeting variance or player execution | C44: Validate spreadsheet findings through simulation and playtest-style scenarios
A45: Ability hit reliability is incomplete | B45: Maximum theoretical damage does not guarantee all attacks connect | C45: Add hit-rate assumptions or simulation for Knife Barrage and other conditional abilities
...

Sheet Cost_Efficiency
A1: Unit_ID | B1: Unit_Name | C1: Role | D1: Cost | E1: HP | F1: DPS | G1: HP_per_Cost | H1: DPS_per_Cost | I1: HP_Index | J1: DPS_Index | K1: HP_Deviation | L1: DPS_Deviation | M1: Role_Avg_HP_per_Cost | N1: Role_Avg_DPS_per_Cost | O1: Role_HP_Index | P1: Role_DPS_Index | Q1: Role_Flag | R1: Attack_Range | S1: Range_per_Cost | T1: Role_Avg_Range | U1: Role_Range_Index | V1: Move_Speed | W1: Mobility_per_Cost | X1: Role_Avg_Mobility | Y1: Role_Mobility_Index
A2: UND_01 | B2: Skeleton Swordsman | C2: Infantry | D2: =VLOOKUP(A2,Unit_Balance!$A$2:$N$13,12,FALSE) -> 85 | E2: =VLOOKUP(A2,Unit_Balance!$A$2:$N$13,6,FALSE) -> 800 | F2: =VLOOKUP(A2,Unit_Balance!$A$2:$N$13,9,FALSE) -> 90 | G2: =E2/D2 -> 9.4117647 | H2: =F2/D2 -> 1.0588235 | I2: =G2/AVERAGE($G$2:$G$13) -> 1.0641852 | J2: =H2/AVERAGE($H$2:$H$13) -> 1.3574866 | K2: =I2-1 -> 0.064185151 | L2: =J2-1 -> 0.35748659 | M2: =AVERAGEIF($C$2:$C$13,C2,$G$2:$G$13) -> 9.6372549 | N2: =AVERAGEIF($C$2:$C$13,C2,$H$2:$H$13) -> 0.96405229 | O2: =G2/M2 -> 0.97660224 | P2: =H2/N2 -> 1.0983051 | Q2: =IF(OR(O2>1.2,O2<0.8,P2>1.2,P2<0.8),"CHECK",IF(OR(O2>1.1,O2<0.9,P2>1.1,P2<0.9),"WATCH","OK")) -> OK | R2: =VLOOKUP(A2,Unit_Balance!$A:$N,10,FALSE) -> 1 | S2: =R2/D2 -> 0.011764706 | T2: =AVERAGEIF($C$2:$C$13,C2,$S$2:$S$13) -> 0.010958606 | U2: =S2/T2 -> 1.0735586 | V2: =VLOOKUP(A2,Unit_Balance!$A:$N,11,FALSE) -> 2 | W2: =V2/D2 -> 0.023529412 | X2: =AVERAGEIF($C$2:$C$13,C2,$W$2:$W$13) -> 0.024065359 | Y2: =W2/X2 -> 0.97772949
A3: UND_02 | B3: Bone Dragon | C3: Tank | D3: =VLOOKUP(A3,Unit_Balance!$A$2:$N$13,12,FALSE) -> 140 | E3: =VLOOKUP(A3,Unit_Balance!$A$2:$N$13,6,FALSE) -> 1440 | F3: =VLOOKUP(A3,Unit_Balance!$A$2:$N$13,9,FALSE) -> 60 | G3: =E3/D3 -> 10.285714 | H3: =F3/D3 -> 0.42857143 | I3: =G3/AVERAGE($G$2:$G$13) -> 1.1630023 | J3: =H3/AVERAGE($H$2:$H$13) -> 0.54945886 | K3: =I3-1 -> 0.16300234 | L3: =J3-1 -> -0.45054114 | M3: =AVERAGEIF($C$2:$C$13,C3,$G$2:$G$13) -> 11.442247 | N3: =AVERAGEIF($C$2:$C$13,C3,$H$2:$H$13) -> 0.43003663 | O3: =G3/M3 -> 0.89892436 | P3: =H3/N3 -> 0.99659284 | Q3: =IF(OR(O3>1.2,O3<0.8,P3>1.2,P3<0.8),"CHECK",IF(OR(O3>1.1,O3<0.9,P3>1.1,P3<0.9),"WATCH","OK")) -> WATCH | R3: =VLOOKUP(A3,Unit_Balance!$A:$N,10,FALSE) -> 1 | S3: =R3/D3 -> 0.0071428571 | T3: =AVERAGEIF($C$2:$C$13,C3,$S$2:$S$13) -> 0.0071672772 | U3: =S3/T3 -> 0.99659284 | V3: =VLOOKUP(A3,Unit_Balance!$A:$N,11,FALSE) -> 1.4 | W3: =V3/D3 -> 0.01 | X3: =AVERAGEIF($C$2:$C$13,C3,$W$2:$W$13) -> 0.0096581197 | Y3: =W3/X3 -> 1.0353982
A4: UND_03 | B4: Spear Devil | C4: Ranged | D4: =VLOOKUP(A4,Unit_Balance!$A$2:$N$13,12,FALSE) -> 95 | E4: =VLOOKUP(A4,Unit_Balance!$A$2:$N$13,6,FALSE) -> 800 | F4: =VLOOKUP(A4,Unit_Balance!$A$2:$N$13,9,FALSE) -> 110 | G4: =E4/D4 -> 8.4210526 | H4: =F4/D4 -> 1.1578947 | I4: =G4/AVERAGE($G$2:$G$13) -> 0.95216566 | J4: =H4/AVERAGE($H$2:$H$13) -> 1.4845029 | K4: =I4-1 -> -0.047834338 | L4: =J4-1 -> 0.48450288 | M4: =AVERAGEIF($C$2:$C$13,C4,$G$2:$G$13) -> 7.8979266 | N4: =AVERAGEIF($C$2:$C$13,C4,$H$2:$H$13) -> 1.0859649 | O4: =G4/M4 -> 1.0662359 | P4: =H4/N4 -> 1.0662359 | Q4: =IF(OR(O4>1.2,O4<0.8,P4>1.2,P4<0.8),"CHECK",IF(OR(O4>1.1,O4<0.9,P4>1.1,P4<0.9),"WATCH","OK")) -> OK | R4: =VLOOKUP(A4,Unit_Balance!$A:$N,10,FALSE) -> 5 | S4: =R4/D4 -> 0.052631579 | T4: =AVERAGEIF($C$2:$C$13,C4,$S$2:$S$13) -> 0.04754386 | U4: =S4/T4 -> 1.1070111 | V4: =VLOOKUP(A4,Unit_Balance!$A:$N,11,FALSE) -> 2.2 | W4: =V4/D4 -> 0.023157895 | X4: =AVERAGEIF($C$2:$C$13,C4,$W$2:$W$13) -> 0.018901116 | Y4: =W4/X4 -> 1.2252131
A5: UND_04 | B5: Witch | C5: Support | D5: =VLOOKUP(A5,Unit_Balance!$A$2:$N$13,12,FALSE) -> 110 | E5: =VLOOKUP(A5,Unit_Balance!$A$2:$N$13,6,FALSE) -> 700 | F5: =VLOOKUP(A5,Unit_Balance!$A$2:$N$13,9,FALSE) -> 70 | G5: =E5/D5 -> 6.3636364 | H5: =F5/D5 -> 0.63636364 | I5: =G5/AVERAGE($G$2:$G$13) -> 0.71953428 | J5: =H5/AVERAGE($H$2:$H$13) -> 0.81586315 | K5: =I5-1 -> -0.28046572 | L5: =J5-1 -> -0.18413685 | M5: =AVERAGEIF($C$2:$C$13,C5,$G$2:$G$13) -> 6.3989899 | N5: =AVERAGEIF($C$2:$C$13,C5,$H$2:$H$13) -> 0.63989899 | O5: =G5/M5 -> 0.99447514 | P5: =H5/N5 -> 0.99447514 | Q5: =IF(OR(O5>1.2,O5<0.8,P5>1.2,P5<0.8),"CHECK",IF(OR(O5>1.1,O5<0.9,P5>1.1,P5<0.9),"WATCH","OK")) -> OK | R5: =VLOOKUP(A5,Unit_Balance!$A:$N,10,FALSE) -> 5 | S5: =R5/D5 -> 0.045454545 | T5: =AVERAGEIF($C$2:$C$13,C5,$S$2:$S$13) -> 0.032373737 | U5: =S5/T5 -> 1.4040562 | V5: =VLOOKUP(A5,Unit_Balance!$A:$N,11,FALSE) -> 1.6 | W5: =V5/D5 -> 0.014545455 | X5: =AVERAGEIF($C$2:$C$13,C5,$W$2:$W$13) -> 0.019070707 | Y5: =W5/X5 -> 0.76271186
A6: ELF_01 | B6: Elven Swordsman | C6: Infantry | D6: =VLOOKUP(A6,Unit_Balance!$A$2:$N$13,12,FALSE) -> 100 | E6: =VLOOKUP(A6,Unit_Balance!$A$2:$N$13,6,FALSE) -> 950 | F6: =VLOOKUP(A6,Unit_Balance!$A$2:$N$13,9,FALSE) -> 100 | G6: =E6/D6 -> 9.5 | H6: =F6/D6 -> 1 | I6: =G6/AVERAGE($G$2:$G$13) -> 1.0741619 | J6: =H6/AVERAGE($H$2:$H$13) -> 1.2820707 | K6: =I6-1 -> 0.074161887 | L6: =J6-1 -> 0.28207067 | M6: =AVERAGEIF($C$2:$C$13,C6,$G$2:$G$13) -> 9.6372549 | N6: =AVERAGEIF($C$2:$C$13,C6,$H$2:$H$13) -> 0.96405229 | O6: =G6/M6 -> 0.98575788 | P6: =H6/N6 -> 1.0372881 | Q6: =IF(OR(O6>1.2,O6<0.8,P6>1.2,P6<0.8),"CHECK",IF(OR(O6>1.1,O6<0.9,P6>1.1,P6<0.9),"WATCH","OK")) -> OK | R6: =VLOOKUP(A6,Unit_Balance!$A:$N,10,FALSE) -> 1 | S6: =R6/D6 -> 0.01 | T6: =AVERAGEIF($C$2:$C$13,C6,$S$2:$S$13) -> 0.010958606 | U6: =S6/T6 -> 0.91252485 | V6: =VLOOKUP(A6,Unit_Balance!$A:$N,11,FALSE) -> 2.2 | W6: =V6/D6 -> 0.022 | X6: =AVERAGEIF($C$2:$C$13,C6,$W$2:$W$13) -> 0.024065359 | Y6: =W6/X6 -> 0.91417708
A7: ELF_02 | B7: Great Forest Bear | C7: Tank | D7: =VLOOKUP(A7,Unit_Balance!$A$2:$N$13,12,FALSE) -> 130 | E7: =VLOOKUP(A7,Unit_Balance!$A$2:$N$13,6,FALSE) -> 1600 | F7: =VLOOKUP(A7,Unit_Balance!$A$2:$N$13,9,FALSE) -> 60 | G7: =E7/D7 -> 12.307692 | H7: =F7/D7 -> 0.46153846 | I7: =G7/AVERAGE($G$2:$G$13) -> 1.3916267 | J7: =H7/AVERAGE($H$2:$H$13) -> 0.59172492 | K7: =I7-1 -> 0.39162674 | L7: =J7-1 -> -0.40827508 | M7: =AVERAGEIF($C$2:$C$13,C7,$G$2:$G$13) -> 11.442247 | N7: =AVERAGEIF($C$2:$C$13,C7,$H$2:$H$13) -> 0.43003663 | O7: =G7/M7 -> 1.075636 | P7: =H7/N7 -> 1.0732538 | Q7: =IF(OR(O7>1.2,O7<0.8,P7>1.2,P7<0.8),"CHECK",IF(OR(O7>1.1,O7<0.9,P7>1.1,P7<0.9),"WATCH","OK")) -> OK | R7: =VLOOKUP(A7,Unit_Balance!$A:$N,10,FALSE) -> 1 | S7: =R7/D7 -> 0.0076923077 | T7: =AVERAGEIF($C$2:$C$13,C7,$S$2:$S$13) -> 0.0071672772 | U7: =S7/T7 -> 1.0732538 | V7: =VLOOKUP(A7,Unit_Balance!$A:$N,11,FALSE) -> 1.6 | W7: =V7/D7 -> 0.012307692 | X7: =AVERAGEIF($C$2:$C$13,C7,$W$2:$W$13) -> 0.0096581197 | Y7: =W7/X7 -> 1.2743363
A8: ELF_03 | B8: Elven Mage | C8: Ranged | D8: =VLOOKUP(A8,Unit_Balance!$A$2:$N$13,12,FALSE) -> 110 | E8: =VLOOKUP(A8,Unit_Balance!$A$2:$N$13,6,FALSE) -> 800 | F8: =VLOOKUP(A8,Unit_Balance!$A$2:$N$13,9,FALSE) -> 110 | G8: =E8/D8 -> 7.2727273 | H8: =F8/D8 -> 1 | I8: =G8/AVERAGE($G$2:$G$13) -> 0.82232489 | J8: =H8/AVERAGE($H$2:$H$13) -> 1.2820707 | K8: =I8-1 -> -0.17767511 | L8: =J8-1 -> 0.28207067 | M8: =AVERAGEIF($C$2:$C$13,C8,$G$2:$G$13) -> 7.8979266 | N8: =AVERAGEIF($C$2:$C$13,C8,$H$2:$H$13) -> 1.0859649 | O8: =G8/M8 -> 0.92084006 | P8: =H8/N8 -> 0.92084006 | Q8: =IF(OR(O8>1.2,O8<0.8,P8>1.2,P8<0.8),"CHECK",IF(OR(O8>1.1,O8<0.9,P8>1.1,P8<0.9),"WATCH","OK")) -> OK | R8: =VLOOKUP(A8,Unit_Balance!$A:$N,10,FALSE) -> 5.5 | S8: =R8/D8 -> 0.05 | T8: =AVERAGEIF($C$2:$C$13,C8,$S$2:$S$13) -> 0.04754386 | U8: =S8/T8 -> 1.0516605 | V8: =VLOOKUP(A8,Unit_Balance!$A:$N,11,FALSE) -> 1.6 | W8: =V8/D8 -> 0.014545455 | X8: =AVERAGEIF($C$2:$C$13,C8,$W$2:$W$13) -> 0.018901116 | Y8: =W8/X8 -> 0.76955531
A9: ELF_04 | B9: Elven Scholar | C9: Support | D9: =VLOOKUP(A9,Unit_Balance!$A$2:$N$13,12,FALSE) -> 120 | E9: =VLOOKUP(A9,Unit_Balance!$A$2:$N$13,6,FALSE) -> 700 | F9: =VLOOKUP(A9,Unit_Balance!$A$2:$N$13,9,FALSE) -> 70 | G9: =E9/D9 -> 5.8333333 | H9: =F9/D9 -> 0.58333333 | I9: =G9/AVERAGE($G$2:$G$13) -> 0.65957309 | J9: =H9/AVERAGE($H$2:$H$13) -> 0.74787456 | K9: =I9-1 -> -0.34042691 | L9: =J9-1 -> -0.25212544 | M9: =AVERAGEIF($C$2:$C$13,C9,$G$2:$G$13) -> 6.3989899 | N9: =AVERAGEIF($C$2:$C$13,C9,$H$2:$H$13) -> 0.63989899 | O9: =G9/M9 -> 0.91160221 | P9: =H9/N9 -> 0.91160221 | Q9: =IF(OR(O9>1.2,O9<0.8,P9>1.2,P9<0.8),"CHECK",IF(OR(O9>1.1,O9<0.9,P9>1.1,P9<0.9),"WATCH","OK")) -> OK | R9: =VLOOKUP(A9,Unit_Balance!$A:$N,10,FALSE) -> 5 | S9: =R9/D9 -> 0.041666667 | T9: =AVERAGEIF($C$2:$C$13,C9,$S$2:$S$13) -> 0.032373737 | U9: =S9/T9 -> 1.2870515 | V9: =VLOOKUP(A9,Unit_Balance!$A:$N,11,FALSE) -> 2 | W9: =V9/D9 -> 0.016666667 | X9: =AVERAGEIF($C$2:$C$13,C9,$W$2:$W$13) -> 0.019070707 | Y9: =W9/X9 -> 0.87394068
A10: HOR_01 | B10: Blade Goblin | C10: Infantry | D10: =VLOOKUP(A10,Unit_Balance!$A$2:$N$13,12,FALSE) -> 90 | E10: =VLOOKUP(A10,Unit_Balance!$A$2:$N$13,6,FALSE) -> 900 | F10: =VLOOKUP(A10,Unit_Balance!$A$2:$N$13,9,FALSE) -> 75 | G10: =E10/D10 -> 10 | H10: =F10/D10 -> 0.83333333 | I10: =G10/AVERAGE($G$2:$G$13) -> 1.1306967 | J10: =H10/AVERAGE($H$2:$H$13) -> 1.0683922 | K10: =I10-1 -> 0.13069672 | L10: =J10-1 -> 0.068392224 | M10: =AVERAGEIF($C$2:$C$13,C10,$G$2:$G$13) -> 9.6372549 | N10: =AVERAGEIF($C$2:$C$13,C10,$H$2:$H$13) -> 0.96405229 | O10: =G10/M10 -> 1.0376399 | P10: =H10/N10 -> 0.86440678 | Q10: =IF(OR(O10>1.2,O10<0.8,P10>1.2,P10<0.8),"CHECK",IF(OR(O10>1.1,O10<0.9,P10>1.1,P10<0.9),"WATCH","OK")) -> WATCH | R10: =VLOOKUP(A10,Unit_Balance!$A:$N,10,FALSE) -> 1 | S10: =R10/D10 -> 0.011111111 | T10: =AVERAGEIF($C$2:$C$13,C10,$S$2:$S$13) -> 0.010958606 | U10: =S10/T10 -> 1.0139165 | V10: =VLOOKUP(A10,Unit_Balance!$A:$N,11,FALSE) -> 2.4 | W10: =V10/D10 -> 0.026666667 | X10: =AVERAGEIF($C$2:$C$13,C10,$W$2:$W$13) -> 0.024065359 | Y10: =W10/X10 -> 1.1080934
A11: HOR_02 | B11: Stone Ogre | C11: Tank | D11: =VLOOKUP(A11,Unit_Balance!$A$2:$N$13,12,FALSE) -> 150 | E11: =VLOOKUP(A11,Unit_Balance!$A$2:$N$13,6,FALSE) -> 1760 | F11: =VLOOKUP(A11,Unit_Balance!$A$2:$N$13,9,FALSE) -> 60 | G11: =E11/D11 -> 11.733333 | H11: =F11/D11 -> 0.4 | I11: =G11/AVERAGE($G$2:$G$13) -> 1.3266842 | J11: =H11/AVERAGE($H$2:$H$13) -> 0.51282827 | K11: =I11-1 -> 0.32668416 | L11: =J11-1 -> -0.48717173 | M11: =AVERAGEIF($C$2:$C$13,C11,$G$2:$G$13) -> 11.442247 | N11: =AVERAGEIF($C$2:$C$13,C11,$H$2:$H$13) -> 0.43003663 | O11: =G11/M11 -> 1.0254396 | P11: =H11/N11 -> 0.93015332 | Q11: =IF(OR(O11>1.2,O11<0.8,P11>1.2,P11<0.8),"CHECK",IF(OR(O11>1.1,O11<0.9,P11>1.1,P11<0.9),"WATCH","OK")) -> OK | R11: =VLOOKUP(A11,Unit_Balance!$A:$N,10,FALSE) -> 1 | S11: =R11/D11 -> 0.0066666667 | T11: =AVERAGEIF($C$2:$C$13,C11,$S$2:$S$13) -> 0.0071672772 | U11: =S11/T11 -> 0.93015332 | V11: =VLOOKUP(A11,Unit_Balance!$A:$N,11,FALSE) -> 1 | W11: =V11/D11 -> 0.0066666667 | X11: =AVERAGEIF($C$2:$C$13,C11,$W$2:$W$13) -> 0.0096581197 | Y11: =W11/X11 -> 0.69026549
A12: HOR_03 | B12: Orc Thrower | C12: Ranged | D12: =VLOOKUP(A12,Unit_Balance!$A$2:$N$13,12,FALSE) -> 100 | E12: =VLOOKUP(A12,Unit_Balance!$A$2:$N$13,6,FALSE) -> 800 | F12: =VLOOKUP(A12,Unit_Balance!$A$2:$N$13,9,FALSE) -> 110 | G12: =E12/D12 -> 8 | H12: =F12/D12 -> 1.1 | I12: =G12/AVERAGE($G$2:$G$13) -> 0.90455738 | J12: =H12/AVERAGE($H$2:$H$13) -> 1.4102777 | K12: =I12-1 -> -0.095442621 | L12: =J12-1 -> 0.41027774 | M12: =AVERAGEIF($C$2:$C$13,C12,$G$2:$G$13) -> 7.8979266 | N12: =AVERAGEIF($C$2:$C$13,C12,$H$2:$H$13) -> 1.0859649 | O12: =G12/M12 -> 1.0129241 | P12: =H12/N12 -> 1.0129241 | Q12: =IF(OR(O12>1.2,O12<0.8,P12>1.2,P12<0.8),"CHECK",IF(OR(O12>1.1,O12<0.9,P12>1.1,P12<0.9),"WATCH","OK")) -> OK | R12: =VLOOKUP(A12,Unit_Balance!$A:$N,10,FALSE) -> 4 | S12: =R12/D12 -> 0.04 | T12: =AVERAGEIF($C$2:$C$13,C12,$S$2:$S$13) -> 0.04754386 | U12: =S12/T12 -> 0.84132841 | V12: =VLOOKUP(A12,Unit_Balance!$A:$N,11,FALSE) -> 1.9 | W12: =V12/D12 -> 0.019 | X12: =AVERAGEIF($C$2:$C$13,C12,$W$2:$W$13) -> 0.018901116 | Y12: =W12/X12 -> 1.0052316
A13: HOR_04 | B13: Boneclub Troll | C13: Support | D13: =VLOOKUP(A13,Unit_Balance!$A$2:$N$13,12,FALSE) -> 100 | E13: =VLOOKUP(A13,Unit_Balance!$A$2:$N$13,6,FALSE) -> 700 | F13: =VLOOKUP(A13,Unit_Balance!$A$2:$N$13,9,FALSE) -> 70 | G13: =E13/D13 -> 7 | H13: =F13/D13 -> 0.7 | I13: =G13/AVERAGE($G$2:$G$13) -> 0.79148771 | J13: =H13/AVERAGE($H$2:$H$13) -> 0.89744947 | K13: =I13-1 -> -0.20851229 | L13: =J13-1 -> -0.10255053 | M13: =AVERAGEIF($C$2:$C$13,C13,$G$2:$G$13) -> 6.3989899 | N13: =AVERAGEIF($C$2:$C$13,C13,$H$2:$H$13) -> 0.63989899 | O13: =G13/M13 -> 1.0939227 | P13: =H13/N13 -> 1.0939227 | Q13: =IF(OR(O13>1.2,O13<0.8,P13>1.2,P13<0.8),"CHECK",IF(OR(O13>1.1,O13<0.9,P13>1.1,P13<0.9),"WATCH","OK")) -> OK | R13: =VLOOKUP(A13,Unit_Balance!$A:$N,10,FALSE) -> 1 | S13: =R13/D13 -> 0.01 | T13: =AVERAGEIF($C$2:$C$13,C13,$S$2:$S$13) -> 0.032373737 | U13: =S13/T13 -> 0.30889236 | V13: =VLOOKUP(A13,Unit_Balance!$A:$N,11,FALSE) -> 2.6 | W13: =V13/D13 -> 0.026 | X13: =AVERAGEIF($C$2:$C$13,C13,$W$2:$W$13) -> 0.019070707 | Y13: =W13/X13 -> 1.3633475

Sheet Ability_Analysis
A1: Analysis_ID | B1: Unit_ID | C1: Ability | D1: Metric | E1: Base_Value | F1: Ability_Value | G1: Change_Percent | H1: Notes
A2: ABL_001 | B2: HOR_01 | C2: Blood Rush | D2: DPS_During_Ability | E2: 75 | F2: 112.5 | G2: =(F2-E2)/E2 -> 0.5 | H2: Assumes continuous attacking
A3: ABL_002 | B3: HOR_01 | C3: Blood Rush | D3: Damage_4s | E3: 300 | F3: 450 | G3: =(F3-E3)/E3 -> 0.5 | H3: Assumes continuous attacking for full 4-second window
A4: ABL_003 | B4: HOR_02 | C4: Stone Skin | D4: Effective_HP_During_Ability | E4: 1760 | F4: =E4/(1-40%) -> 2933.3333 | G4: =(F4-E4)/E4 -> 0.66666667 | H4: Only during 4-second Stone Skin effect
A5: ABL_004 | B5: ELF_03 | C5: Focused Bolt | D5: Single_Hit_Damage | E5: 132 | F5: =E5*2.5 -> 330 | G5: =(F5-E5)/E5 -> 1.5 | H5: Assumes Focused Bolt cast completes
A6: ABL_005 | B6: HOR_03 | C6: Knife Barrage | D6: Damage_Per_Knife | E6: 132 | F6: =E6*0.45 -> 59.4 | G6: =(F6-E6)/E6 -> -0.55 | H6: Damage of one individual knife
A7: ABL_006 | B7: HOR_03 | C7: Knife Barrage | D7: Max_Total_Damage | E7: 132 | F7: =E7*0.45*5 -> 297 | G7: =(F7-E7)/E7 -> 1.25 | H7: Maximum damage if all 5 knives hit
A8: ABL_007 | B8: UND_01 | C8: Reassemble | D8: Restored_HP | E8: 800 | F8: =E8*35% -> 280 | G8: =(F8-E8)/E8 -> -0.65 | H8: HP restored after successful Reassemble
A9: ABL_008 | B9: UND_01 | C9: Reassemble | D9: Theoretical_Total_HP | E9: 800 | F9: =E9*(1+35%) -> 1080 | G9: =(F9-E9)/E9 -> 0.35 | H9: Assumes Reassemble succeeds and restored HP is fully consumed
A10: ABL_009 | B10: UND_02 | C10: Death Feast | D10: Heal_Per_Death | E10: 1440 | F10: =E10*3% -> 43.2 | G10: =(F10-E10)/E10 -> -0.97 | H10: Healing generated by one nearby death
A11: ABL_010 | B11: UND_02 | C11: Death Feast | D11: Max_Heal_Per_Second | E11: 1440 | F11: =E11*6% -> 86.4 | G11: =(F11-E11)/E11 -> -0.94 | H11: Maximum healing per second due to ability cap
A12: ABL_011 | B12: UND_03 | C12: Cursed Spear | D12: Target_Damage_After_Debuff | E12: 100 | F12: =E12*(1-15%) -> 85 | G12: =(F12-E12)/E12 -> -0.15 | H12: Normalized target damage after Cursed Spear debuf
A13: ABL_012 | B13: UND_04 | C13: Curse | D13: Target_Attack_Speed_After_Debuff | E13: 100 | F13: =E13*(1-20%) -> 80 | G13: =(F13-E13)/E13 -> -0.2 | H13: Normalized basic Attack Speed; does not affect ability timing
A14: ABL_013 | B14: UND_03; UND_04 | C14: Cursed Spear + Curse | D14: Target_Normalized_DPS | E14: 100 | F14: =E14*(1-15%)*(1-20%) -> 68 | G14: =(F14-E14)/E14 -> -0.32 | H14: Combined theoretical effect when both debuffs are active

Sheet Combat_Scenarios
A1: Scenario_ID | B1: Attacker_ID | C1: Defender_ID | D1: Scenario | E1: Attacker_DPS | F1: Defender_HP | G1: Ability_Modifier | H1: Effective_DPS | I1: Time_to_Kill | J1: Notes | K1: Adjusted_Result | L1: Unit | M1: Result_Description | N1: Finding | O1: Balance_Interpretation | P1: Action | Q1: Risk_Link
A2: SCN_001 | B2: HOR_01 | C2: UND_01 | D2: Goblin vs Skeleton — Base | E2: =Unit_Balance!I10 -> 75 | F2: =Unit_Balance!F2 -> 800 | G2: 1 | H2: =E2*G2 -> 75 | I2: =F2/H2 -> 10.666667 | J2: Baseline; ignores Reassemble | K2: =I2 -> 10.666667 | L2: sec | M2: Baseline TTK | N2: Finding | O2: Balance_Interpretation | P2: Action | Q2: Risk_Link
A3: SCN_002 | B3: HOR_01 | C3: UND_01 | D3: Goblin vs Skeleton — Blood Rush | E3: =Unit_Balance!I10 -> 75 | F3: 800 | G3: =1+Ability_Balance!F35/100 -> 1.5 | H3: =E3*G3 -> 112.5 | I3: =F3/H3 -> 7.1111111 | J3: Blood Rush lasts only 4 sec; theoretical TTK assumes permanent bonus | K3: =4+(F3-H3*4)/E3 -> 8.6666667 | L3: sec | M3: Adjusted TTK with temporary Blood Rush | N3: Baseline TTK = 10.67 sec | O3: Provides a reference combat duration for comparing modified Goblin vs Skeleton scenarios | P3: Keep as baseline reference | Q3: —
A4: SCN_003 | B4: ELF_03 | C4: HOR_02 | D4: Focused Bolt vs Stone Ogre | E4: =Unit_Balance!G8 -> 132 | F4: =Unit_Balance!F11 -> 1760 | G4: 2.5 | H4: =E4*G4 -> 330 | I4: =F4/(E4*G4) -> 5.3333333 | J4: Focused Bolt single-hit analysis; Time_to_Kill represents equivalent number of full-damage bolts, not seconds | K4: =E4*G4*(1-40/100) -> 198 | L4: damage | M4: Focused Bolt damage during Stone Skin | N4: Theoretical TTK = 7.11 sec, but Blood Rush lasts only 4 sec | O4: Blood Rush creates a strong temporary damage window, but the simple TTK calculation overestimates its duration because the bonus does not remain active until the target dies | P4: Recalculate using a two-phase damage model | Q4: —
A5: SCN_004 | B5: HOR_03 | C5: ELF_03 | D5: Knife Barrage vs Elven Mage | E5: =Unit_Balance!G12 -> 132 | F5: 800 | G5: =0.45*5 -> 2.25 | H5: =E5*G5 -> 297 | I5: =ROUNDUP(F5/H5,0) -> 3 | J5: Maximum Knife Barrage damage if all 5 knives hit; no retarget | K5: =H5 -> 297 | L5: damage | M5: Maximum Knife Barrage damage | N5: Focused Bolt deals 330 raw damage and 198 damage during Stone Skin | O5: Stone Skin reduces Focused Bolt damage by 40%, creating a meaningful defensive timing interaction | P5: Keep interaction and validate in combat testing | Q5: —
A6: SCN_005 | B6: UND_03; UND_04 | C6: HOR_01 | D6: Combined Undead Debuffs vs Goblin | E6: =Unit_Balance!I10*(1+Ability_Balance!F35/100) -> 112.5 | F6: 800 | G6: =(1-15/100)*(1-20/100) -> 0.68 | H6: =E6*G6 -> 76.5 | I6: =F6/H6 -> 10.457516 | J6: Steady-state value after both debuffs are active; Cursed Spear requires 3 hits before activation | K6: =H6 -> 76.5 | L6: DPS | M6: Blood Rush DPS after both Undead debuffs are active | N6: Knife Barrage deals up to 297 total damage | O6: A full Knife Barrage deals 2.25x base damage if all five knives hit, but requires the target to remain valid for the full barrage | P6: Test hit reliability and interruption frequency | Q6: —
A7: SCN_006 | B7: UND_01 | C7: UND_01 | D7: Skeleton Reassemble — Effective HP | E7: 800 | F7: 800 | G7: 1.35 | H7: =E7*G7 -> 1080 | J7: Assumes Reassemble succeeds and restored HP is fully consumed | K7: =H7 -> 1080 | L7: HP | M7: Theoretical total HP including Reassemble | N7: Combined Undead debuffs reduce normalized DPS to 68% | O7: Simultaneous Cursed Spear and Curse theoretically reduce sustained DPS by 32%, creating potentially strong debuff synergy | P7: Test combined debuffs against multiple attacker archetypes | Q7: RISK_001
A8: SCN_007 | B8: UND_02 | C8: UND_02 | D8: Bone Dragon — Death Feast per Death | E8: 1440 | F8: 1440 | G8: 0.03 | H8: =E8*G8 -> 43.2 | J8: Healing generated by one nearby death | K8: =H8 -> 43.2 | L8: HP | M8: Death Feast healing from one death | N8: Reassemble increases theoretical Skeleton HP from 800 to 1080 | O8: A successful Reassemble increases theoretical total HP by 35%, but the 4-second delay creates a counterplay window | P8: Test Reassemble success rate in realistic combat | Q8: —
A9: SCN_008 | B9: UND_02 | C9: UND_02 | D9: Bone Dragon — Death Feast Heal Cap | E9: 1440 | F9: 1440 | G9: 0.06 | H9: =E9*G9 -> 86.4 | J9: Maximum Death Feast healing allowed per second | K9: =H9 -> 86.4 | L9: HP/sec | M9: Maximum Death Feast healing per second | N9: One nearby death heals Bone Dragon for 43.2 HP | O9: Individual Death Feast triggers are small, so ability value depends strongly on nearby death frequency | P9: Test healing across different numbers of nearby deaths | Q9: RISK_004
A10: SCN_009 | B10: HOR_01 | C10: UND_04 | D10: Blood Rush vs Curse | E10: 75 | F10: 800 | G10: =1.5*(1-20/100) -> 1.2 | H10: =E10*G10 -> 90 | I10: =F10/H10 -> 8.8888889 | J10: Multiplicative model: Blood Rush bonus combined with Curse Attack Speed reduction | K10: =H10 -> 90 | L10: DPS | M10: Goblin effective DPS during Blood Rush while Cursed | N10: Death Feast healing is capped at 86.4 HP/sec | O10: The healing cap limits extreme sustain when many units die simultaneously | P10: Test whether the cap prevents excessive sustain in large fights | Q10: RISK_004
A11: SCN_010 | B11: HOR_04 | C11: ELF_03 | D11: Bone Smash vs Focused Bolt | E11: 1.5 | F11: 2 | G11: =E11/F11 -> 0.75 | H11: =G11*100 -> 75 | I11: =F11-E11 -> 0.5 | J11: Compares Bone Smash stun duration with Focused Bolt charge time; assumes successful interrupt timing | K11: =H11 -> 75 | L11: % | M11: Stun duration as percentage of Focused Bolt charge time | N11: Blood Rush + Curse produces 90 DPS under the current multiplicative model | O11: Curse partially offsets Blood Rush, but the result depends on the chosen Attack Speed stacking rule | P11: Compare additive and multiplicative stacking models | Q11: RISK_006
A12: SCN_011 | B12: UND_03 | C12: Generic Target | D12: Cursed Spear — Time to Proc | E12: 46054 | F12: 3 | G12: 2 | H12: 46114 | I12: 46114 | J12: Time from first successful hit to third hit; 3 hits require 2 attack intervals | K12: 46114 | L12: sec | M12: Cursed Spear activation time
A13: SCN_012 | B13: Generic Enemy | C13: ELF_02 | D13: Bear — Base Survivability | E13: 100 | F13: 1600 | G13: 1 | H13: 100 | I13: 16 | J13: Baseline survivability model using normalized 100 DPS incoming damage | K13: 16 | L13: sec | M13: Bear baseline theoretical TTK
A14: SCN_013 | B14: Generic Enemy | C14: ELF_02 | D14: Bear + Arcane Shield | E14: 100 | F14: 1600 | G14: 1 | H14: 100 | I14: 46161 | J14: Arcane Shield adds 350 HP; theoretical effective HP = 1600+350 = 1950 | K14: 46161 | L14: sec | M14: Bear theoretical TTK with Arcane Shield

Sheet Interaction_Matrix
